Workbook

Sheet Summary
B2: AtliQ Sales & CRM Memory Assistant
B3: Cost Estimation — Summary Dashboard
B5: Monthly AI tool cost | C5: Annual AI tool cost | D5: Monthly savings vs. manual | E5: % cost saved | F5: Annual savings
B6: =Inference!B39 -> 4.8477453 | C6: =Inference!B40 -> 58.172944 | D6: ='Cost Savings'!B17 -> 774.55225 | E6: ='Cost Savings'!B18 -> 0.99378016 | F6: ='Cost Savings'!B19 -> 9294.6271
B7: Analysis + summaries + emails | C7: 12 × monthly | D7: Human-equivalent − AI cost | E7: vs. manual review baseline | F7: 12 × monthly savings
B10: ROI — for every $1 spent on the AI tool, this saves:
B11: ='Cost Savings'!B17/Inference!B39 -> 159.77577 | C11: in founder + sales rep time value
B14: Where each number comes from
B15: Inference | C15: Token pricing, per-lead/summary/email cost, monthly volume assumptions, monthly cost projection, and a low/mid/high scenario table.
B16: Cost Savings | C16: Manual-review baseline, the AI tool's monthly cost (linked from Inference), the resulting savings, and a break-even calculation.
B17: Model & Assumptions | C17: Why Claude Sonnet 5, infrastructure costs, the real billing data this model is grounded in, and every key assumption in plain language.
B19: This model is fully formula-driven — every number traces back to the Inference or Cost Savings sheet; nothing here is a hardcoded duplicate.

Sheet Inference
A1: AtliQ Sales & CRM Memory Assistant — Cost Estimation
A2: Model inference cost, grounded in real measured usage where possible
A3: Yellow cells are adjustable assumptions. Blue text = input. Green text = link to another sheet.
A5: MODEL & PRICING (Anthropic — Claude Sonnet 5)
A6: Model | B6: claude-sonnet-5
A7: Input cost ($ / 1M tokens) — standard rate | B7: 3
A8: Output cost ($ / 1M tokens) — standard rate | B8: 15
A10: Introductory rate of $2.00 / $10.00 per 1M tokens applies through 31 Aug 2026. The standard rate above is used throughout this model, as the more conservative, sustained estimate. Verified against Anthropic's published pricing page as of Jul 2026.
A12: PER-LEAD ANALYSIS COST — measured from real usage, not theoretical
A13: Full-run cost, 43 leads, 6 categories + suggested actions (actual Anthropic billing) | B13: 3
A14: Leads analyzed in that run | B14: 43
A15: Average cost per lead (measured) | B15: =B13/B14 -> 0.069767442
A17: EXECUTIVE SUMMARY COST — 1 call per Run/Refresh (estimated)
A18: Estimated input tokens | B18: 600
A19: Estimated output tokens | B19: 350
A20: Cost per summary | B20: =(B18*$B$7+B19*$B$8)/1000000 -> 0.00705
A22: GENERATE FOLLOW-UP EMAIL COST — on demand, per click (estimated)
A23: Estimated input tokens | B23: 900
A24: Estimated output tokens | B24: 250
A25: Cost per email generated | B25: =(B23*$B$7+B24*$B$8)/1000000 -> 0.00645
A27: MONTHLY VOLUME ASSUMPTIONS — steady-state AtliQ usage
A28: Total leads in pipeline | B28: 50
A29: Leads needing fresh analysis / week (new email or note activity) | B29: 15
A30: Weeks / month | B30: 4.33
A31: Fresh lead-analyses / month | B31: =B29*B30 -> 64.95
A32: Run/Refresh clicks / month (~1 per business day) | B32: 22
A33: Follow-up emails generated / month | B33: 25
A35: MONTHLY COST PROJECTION
A36: Lead analysis cost / month | B36: =B31*B15 -> 4.5313953
A37: Executive summary cost / month | B37: =B32*B20 -> 0.1551
A38: Follow-up email cost / month | B38: =B33*B25 -> 0.16125
A39: Total monthly cost | B39: =SUM(B36:B38) -> 4.8477453
A40: Total annual cost | B40: =B39*12 -> 58.172944
A42: SCENARIO ANALYSIS — monthly cost at different fresh-analysis volumes
A44: Scenario | B44: Fresh leads/week | C44: Lead analysis/mo | D44: Exec summary/mo | E44: Email/mo | F44: Total/mo
A45: Low | B45: 10 | C45: =B45*$B$30*$B$15 -> 3.0209302 | D45: =$B$32*$B$20 -> 0.1551 | E45: =$B$33*$B$25 -> 0.16125 | F45: =SUM(C45:E45) -> 3.3372802
A46: Mid (matches assumptions above) | B46: =B29 -> 15 | C46: =B46*$B$30*$B$15 -> 4.5313953 | D46: =$B$32*$B$20 -> 0.1551 | E46: =$B$33*$B$25 -> 0.16125 | F46: =SUM(C46:E46) -> 4.8477453
A47: High | B47: 25 | C47: =B47*$B$30*$B$15 -> 7.5523256 | D47: =$B$32*$B$20 -> 0.1551 | E47: =$B$33*$B$25 -> 0.16125 | F47: =SUM(C47:E47) -> 7.8686756
A49: Low/High scenarios vary only the fresh-analysis volume (the largest cost driver); Refresh-click and email volumes are held constant at the assumptions above.
A51: NOTES & ASSUMPTIONS
...

Sheet Cost Savings
A1: Cost Savings — AI Tool vs. Manual Review
A2: What this replaces: a founder or Jay manually re-reading emails and notes against the CRM
A4: MANUAL EFFORT BASELINE
A5: Manual review time per lead needing attention (minutes) | B5: 8
A6: Leads needing fresh review / week | B6: =Inference!B29 -> 15
A7: Manual review hours / week | B7: =B5*B6/60 -> 2
A8: Weeks / month | B8: =Inference!B30 -> 4.33
A9: Manual review hours / month | B9: =B7*B8 -> 8.66
A10: Blended hourly value of founder/seller time ($) | B10: 90
A11: Monthly human-equivalent cost | B11: =B9*B10 -> 779.4
A13: AI TOOL COST
A14: Total AI tool cost / month (linked from Inference sheet) | B14: =Inference!B39 -> 4.8477453
A16: SAVINGS
A17: Total savings / month | B17: =B11-B14 -> 774.55225
A18: % savings | B18: =B17/B11 -> 0.99378016
A19: Annual savings | B19: =B17*12 -> 9294.6271
A21: BREAK-EVEN — how much manual time would need to shrink before this stops paying off
A22: Break-even manual review time per lead (minutes) | B22: =B14*60/(B6*B8*B10) -> 0.049758741
A23: At any manual review time above this many minutes/lead, the AI tool is cheaper. The assumed 8 min/lead is well above this line, so the tool is cost-positive even for very fast manual reviewers.
A25: NOTES & ASSUMPTIONS
A26: • This compares the AI tool's real running cost against the time a person would spend manually cross-referencing the same leads — not against doing nothing.
A27: • 8 minutes/lead is a conservative estimate for reading linked emails/notes and comparing them to the CRM by hand; some leads (e.g. FinEdge Bank, with 3+ linked documents) would genuinely take longer.
A28: • $90/hour is a placeholder blended rate for founder/seller time — AtliQ should replace this with a real number before relying on this figure externally.
A29: • This is a supporting, illustrative metric — the PRD's actual North Star is stale high-value leads trending to zero, not cost savings alone.

Sheet Model & Assumptions
A1: Model Choice, Infrastructure & Key Assumptions
A3: MODEL CHOICE
A4: Which model? | B4: Claude Sonnet 5 (claude-sonnet-5), via the Anthropic API.
A5: Why this model? | B5: Strong instruction-following for the grounding/verbatim-quote guardrail (every finding must trace to real source text); native structured/schema-constrained output support; more than sufficient quality for extraction and comparison tasks at this scope.
A6: Why not RAG / embeddings? | B6: Each lead's linked-document set is small (a handful of emails/notes), so passing the full set directly in context is simpler and more reliable than building a retrieval pipeline for marginal benefit at this data volume. See AI PRD, Section 3.
A7: Why not fine-tuning? | B7: No labelled training data exists yet at the volume needed to fine-tune responsibly. Prompt + structured output is the right default for v1; revisit once real human-agreement data accumulates in production.
A8: Alternate model used during prototyping? | B8: Groq (Llama 3.3 70B) — free tier, used temporarily during development while Anthropic billing was being set up. Switched back to Claude Sonnet 5 once funded, since it's the intended production model.
A10: INFRASTRUCTURE
A11: Hosting | B11: Streamlit Community Cloud — free tier, $0/month.
A12: Code hosting | B12: GitHub — free, public repository.
A13: Storage / caching | B13: Local JSON files (analysis_cache.json, findings_history.json) — no database cost at this scale.
A14: Total infrastructure cost | B14: $0/month at prototype and early-pilot scale.
A16: REAL MEASURED DATA USED IN THIS ESTIMATE
A17: 24 Jul 2026 | B17: Full 43-lead run, original 4-category schema — actual Anthropic billing: $0.32.
A18: Late Jul 2026 | B18: Full 43-lead re-run after adding 2 categories + suggested actions (6 categories total) — actual Anthropic billing: $3.00. Used as the basis for the measured per-lead cost in the Inference sheet.
A19: Source | B19: platform.claude.com → Cost — both figures are real billing data, not projections.
A21: KEY ASSUMPTIONS
A22: Adjustable — see yellow cells on the Inference and Cost Savings sheets.
A23: Pipeline size | B23: 50 leads at steady state (up from the current 43, allowing for growth).
A24: Fresh analysis volume | B24: 15 leads/week receive new email or meeting-note activity requiring re-analysis; the rest are served from cache at $0.
A25: Run frequency | B25: ~22 Run/Refresh clicks/month (roughly once per business day).
A26: Email generation volume | B26: 25 draft follow-up emails generated/month, reflecting typical weekly Urgent-lead volume.
